[05.05.2018 00:18:33] send_to_channel.py:14 ERROR - Exception of type ConnectionError in send_new_fight(): HTTPSConnectionPool(host='api.telegram.org', port=443): Max retries exceeded with url: /bot581713419:AAFo2fijVOtEMDqJphKV74AbRTRrePIHY7U/sendMessage?chat_id=-1001336404624&text=%2ABrazil&parse_mode=Markdown (Caused by NewConnectionError('<urllib3.connection.VerifiedHTTPSConnection object at 0x10da65438>: Failed to establish a new connection: [Errno 65] No route to host',))
[05.05.2018 00:18:33] send_to_channel.py:16 INFO - Finished sending.
[05.05.2018 00:19:57] send_to_channel.py:14 ERROR - Exception of type ConnectionError in send_new_fight(): HTTPSConnectionPool(host='api.telegram.org', port=443): Max retries exceeded with url: /bot581713419:AAFo2fijVOtEMDqJphKV74AbRTRrePIHY7U/sendMessage?chat_id=-1001336404624&text=%2ABrazil+F2%2C+Doubles%0ADischinger+E+%2F+Leite+W+-+Tabilo+A+%2F+Zukas+M%2A+%D0%A1%D1%87%D1%91%D1%82%3A+0-2%0A+%D0%A4%D0%B0%D0%B2%D0%BE%D1%80%D0%B8%D1%82%3A+2%0A&parse_mode=Markdown (Caused by NewConnectionError('<urllib3.connection.VerifiedHTTPSConnection object at 0x1110a9630>: Failed to establish a new connection: [Errno 65] No route to host',))
[05.05.2018 00:19:57] send_to_channel.py:16 INFO - Finished sending.
[09.05.2018 12:13:42] send_to_channel.py:16 INFO - Finished sending.
[09.05.2018 12:13:44] send_to_channel.py:16 INFO - Finished sending.
[09.05.2018 12:13:45] send_to_channel.py:16 INFO - Finished sending.
